<?xml version="1.0" encoding="utf-8"?>
<!-- This URDF was automatically created by SolidWorks to URDF Exporter! Originally created by Stephen Brawner (brawner@gmail.com) 
     Commit Version: 1.6.0-4-g7f85cfe  Build Version: 1.6.7995.38578
     For more information, please see http://wiki.ros.org/sw_urdf_exporter -->
<robot
  name="Poppy_Humanoid.SLDASM">
  <link
    name="pelvis">
    <inertial>
      <origin
        xyz="-0.000182673739714415 -0.000250000234069813 0.00155106487837646"
        rpy="0 0 0" />
      <mass
        value="0.185914892869111" />
      <inertia
        ixx="8.32806339991228E-05"
        ixy="-3.43586517476164E-09"
        ixz="-7.59692647482749E-06"
        iyy="8.60688415180713E-05"
        iyz="2.91713589838576E-06"
        izz="4.94037348076893E-05" />
    </inertial>
    <visual>
      <origin
        xyz="0 0 0"
        rpy="0 0 0" />
      <geometry>
        <mesh
          filename="package://Poppy_Humanoid.SLDASM/meshes/pelvis.STL" />
      </geometry>
      <material
        name="">
        <color
          rgba="0.752941176470588 0.752941176470588 0.752941176470588 1" />
      </material>
    </visual>
    <collision>
      <origin
        xyz="0 0 0"
        rpy="0 0 0" />
      <geometry>
        <mesh
          filename="package://Poppy_Humanoid.SLDASM/meshes/pelvis.STL" />
      </geometry>
    </collision>
  </link>
  <link
    name="r_hip">
    <inertial>
      <origin
        xyz="-0.0415012578953106 0.0200395877573377 -0.00489206155964109"
        rpy="0 0 0" />
      <mass
        value="0.0846246575014913" />
      <inertia
        ixx="2.55427941608754E-05"
        ixy="1.49612256802435E-07"
        ixz="8.91603631937411E-07"
        iyy="2.45764594226374E-05"
        iyz="2.62029184394319E-07"
        izz="1.76714771621758E-05" />
    </inertial>
    <visual>
      <origin
        xyz="0 0 0"
        rpy="0 0 0" />
      <geometry>
        <mesh
          filename="package://Poppy_Humanoid.SLDASM/meshes/r_hip.STL" />
      </geometry>
      <material
        name="">
        <color
          rgba="0.752941176470588 0.752941176470588 0.752941176470588 1" />
      </material>
    </visual>
    <collision>
      <origin
        xyz="0 0 0"
        rpy="0 0 0" />
      <geometry>
        <mesh
          filename="package://Poppy_Humanoid.SLDASM/meshes/r_hip.STL" />
      </geometry>
    </collision>
  </link>
  <joint
    name="r_hip_x"
    type="continuous">
    <origin
      xyz="-0.022542 0 0"
      rpy="1.5708 -0.023715 0" />
    <parent
      link="pelvis" />
    <child
      link="r_hip" />
    <axis
      xyz="0 0 1" />
  </joint>
  <link
    name="r_hip_motor">
    <inertial>
      <origin
        xyz="-0.00105990332243883 -0.0222006779501601 -0.0142877349308152"
        rpy="0 0 0" />
      <mass
        value="0.139059608870605" />
      <inertia
        ixx="4.4670116528047E-05"
        ixy="1.83248999773241E-07"
        ixz="-1.43769637755972E-07"
        iyy="5.24003435015609E-05"
        iyz="-1.75498555335875E-08"
        izz="2.9737079341043E-05" />
    </inertial>
    <visual>
      <origin
        xyz="0 0 0"
        rpy="0 0 0" />
      <geometry>
        <mesh
          filename="package://Poppy_Humanoid.SLDASM/meshes/r_hip_motor.STL" />
      </geometry>
      <material
        name="">
        <color
          rgba="0.752941176470588 0.752941176470588 0.752941176470588 1" />
      </material>
    </visual>
    <collision>
      <origin
        xyz="0 0 0"
        rpy="0 0 0" />
      <geometry>
        <mesh
          filename="package://Poppy_Humanoid.SLDASM/meshes/r_hip_motor.STL" />
      </geometry>
    </collision>
  </link>
  <joint
    name="r_hip_z"
    type="continuous">
    <origin
      xyz="-0.0439986111539757 0 0.005"
      rpy="0 -0.044100720886384 0" />
    <parent
      link="r_hip" />
    <child
      link="r_hip_motor" />
    <axis
      xyz="0 1 0" />
  </joint>
  <link
    name="r_thigh">
    <inertial>
      <origin
        xyz="-0.0039202732605968 -0.141663735617744 -0.00749831357576491"
        rpy="0 0 0" />
      <mass
        value="0.117089500287638" />
      <inertia
        ixx="0.000149368178187712"
        ixy="-2.3755864098823E-06"
        ixz="2.10893738615726E-07"
        iyy="4.04505705632789E-05"
        iyz="4.10668052140772E-06"
        izz="0.000152512039589024" />
    </inertial>
    <visual>
      <origin
        xyz="0 0 0"
        rpy="0 0 0" />
      <geometry>
        <mesh
          filename="package://Poppy_Humanoid.SLDASM/meshes/r_thigh.STL" />
      </geometry>
      <material
        name="">
        <color
          rgba="0.752941176470588 0.752941176470588 0.752941176470588 1" />
      </material>
    </visual>
    <collision>
      <origin
        xyz="0 0 0"
        rpy="0 0 0" />
      <geometry>
        <mesh
          filename="package://Poppy_Humanoid.SLDASM/meshes/r_thigh.STL" />
      </geometry>
    </collision>
  </link>
  <joint
    name="r_hip_y"
    type="continuous">
    <origin
      xyz="0 -0.024000000000001 0"
      rpy="-0.0654809290674927 0 0" />
    <parent
      link="r_hip_motor" />
    <child
      link="r_thigh" />
    <axis
      xyz="1 0 0" />
  </joint>
  <link
    name="r_shin">
    <inertial>
      <origin
        xyz="0.0228369633709382 -0.137654975647823 -0.00807120940836338"
        rpy="0 0 0" />
      <mass
        value="0.110791837142992" />
      <inertia
        ixx="0.000138706421537834"
        ixy="1.4436097428297E-05"
        ixz="2.25583264874754E-07"
        iyy="3.6169833273468E-05"
        iyz="-2.35687327803447E-06"
        izz="0.000137984409938588" />
    </inertial>
    <visual>
      <origin
        xyz="0 0 0"
        rpy="0 0 0" />
      <geometry>
        <mesh
          filename="package://Poppy_Humanoid.SLDASM/meshes/r_shin.STL" />
      </geometry>
      <material
        name="">
        <color
          rgba="0.752941176470588 0.752941176470588 0.752941176470588 1" />
      </material>
    </visual>
    <collision>
      <origin
        xyz="0 0 0"
        rpy="0 0 0" />
      <geometry>
        <mesh
          filename="package://Poppy_Humanoid.SLDASM/meshes/r_shin.STL" />
      </geometry>
    </collision>
  </link>
  <joint
    name="r_knee_y"
    type="continuous">
    <origin
      xyz="0 -0.182 0"
      rpy="-1.57079632679487 1.544754172667 -1.57079632679487" />
    <parent
      link="r_thigh" />
    <child
      link="r_shin" />
    <axis
      xyz="0 0 1" />
  </joint>
  <link
    name="r_foot">
    <inertial>
      <origin
        xyz="-0.0073948165321286 -0.027734912000438 -0.00286549359927545"
        rpy="0 0 0" />
      <mass
        value="0.11592937139898" />
      <inertia
        ixx="5.26025368664994E-05"
        ixy="1.24082920388534E-06"
        ixz="1.94285357931599E-07"
        iyy="0.000104237398332921"
        iyz="2.5046988585082E-08"
        izz="5.69669655602634E-05" />
    </inertial>
    <visual>
      <origin
        xyz="0 0 0"
        rpy="0 0 0" />
      <geometry>
        <mesh
          filename="package://Poppy_Humanoid.SLDASM/meshes/r_foot.STL" />
      </geometry>
      <material
        name="">
        <color
          rgba="0.792156862745098 0.819607843137255 0.933333333333333 1" />
      </material>
    </visual>
    <collision>
      <origin
        xyz="0 0 0"
        rpy="0 0 0" />
      <geometry>
        <mesh
          filename="package://Poppy_Humanoid.SLDASM/meshes/r_foot.STL" />
      </geometry>
    </collision>
  </link>
  <joint
    name="r_ankle_y"
    type="continuous">
    <origin
      xyz="0 -0.18 0"
      rpy="0.820889590068429 -1.57079631189374 -0.719479139420092" />
    <parent
      link="r_shin" />
    <child
      link="r_foot" />
    <axis
      xyz="0.998746813392867 -0.02396433575299 -0.0439376074623014" />
  </joint>
  <link
    name="l_hip">
    <inertial>
      <origin
        xyz="0.0410806342669983 0.0208740074170932 -0.00488821216996397"
        rpy="0 0 0" />
      <mass
        value="0.0846364219790961" />
      <inertia
        ixx="2.55552670100875E-05"
        ixy="-1.34315252866312E-07"
        ixz="-8.90932613762029E-07"
        iyy="2.45834657744998E-05"
        iyz="2.47008503740968E-07"
        izz="1.76828037093385E-05" />
    </inertial>
    <visual>
      <origin
        xyz="0 0 0"
        rpy="0 0 0" />
      <geometry>
        <mesh
          filename="package://Poppy_Humanoid.SLDASM/meshes/l_hip.STL" />
      </geometry>
      <material
        name="">
        <color
          rgba="0.752941176470588 0.752941176470588 0.752941176470588 1" />
      </material>
    </visual>
    <collision>
      <origin
        xyz="0 0 0"
        rpy="0 0 0" />
      <geometry>
        <mesh
          filename="package://Poppy_Humanoid.SLDASM/meshes/l_hip.STL" />
      </geometry>
    </collision>
  </link>
  <joint
    name="l_hip_x"
    type="continuous">
    <origin
      xyz="0.022542 0 0"
      rpy="1.5708 0 0" />
    <parent
      link="pelvis" />
    <child
      link="l_hip" />
    <axis
      xyz="0 0 1" />
  </joint>
  <link
    name="l_hip_motor">
    <inertial>
      <origin
        xyz="0.00262043745914695 -0.0212953411759664 -0.0141056332799044"
        rpy="0 0 0" />
      <mass
        value="0.139059608910293" />
      <inertia
        ixx="4.45651527706117E-05"
        ixy="-3.35712120642385E-07"
        ixz="1.31694443853926E-06"
        iyy="5.2389705411507E-05"
        iyz="-6.15434482686572E-08"
        izz="2.9852681225609E-05" />
    </inertial>
    <visual>
      <origin
        xyz="0 0 0"
        rpy="0 0 0" />
      <geometry>
        <mesh
          filename="package://Poppy_Humanoid.SLDASM/meshes/l_hip_motor.STL" />
      </geometry>
      <material
        name="">
        <color
          rgba="0.752941176470588 0.752941176470588 0.752941176470588 1" />
      </material>
    </visual>
    <collision>
      <origin
        xyz="0 0 0"
        rpy="0 0 0" />
      <geometry>
        <mesh
          filename="package://Poppy_Humanoid.SLDASM/meshes/l_hip_motor.STL" />
      </geometry>
    </collision>
  </link>
  <joint
    name="l_hip_z"
    type="continuous">
    <origin
      xyz="0.0439986111539756 0 0.00499999999999817"
      rpy="0 0.12300371754066 0" />
    <parent
      link="l_hip" />
    <child
      link="l_hip_motor" />
    <axis
      xyz="0 1 0" />
  </joint>
  <link
    name="l_thigh">
    <inertial>
      <origin
        xyz="0.00640344886752202 -0.140896925734218 1.51943889819955E-05"
        rpy="0 0 0" />
      <mass
        value="0.117090716012196" />
      <inertia
        ixx="0.000149355885116268"
        ixy="3.34325049213702E-06"
        ixz="-6.75990980494532E-07"
        iyy="4.12258736326751E-05"
        iyz="9.85337194549661E-06"
        izz="0.00015175088063748" />
    </inertial>
    <visual>
      <origin
        xyz="0 0 0"
        rpy="0 0 0" />
      <geometry>
        <mesh
          filename="package://Poppy_Humanoid.SLDASM/meshes/l_thigh.STL" />
      </geometry>
      <material
        name="">
        <color
          rgba="0.752941176470588 0.752941176470588 0.752941176470588 1" />
      </material>
    </visual>
    <collision>
      <origin
        xyz="0 0 0"
        rpy="0 0 0" />
      <geometry>
        <mesh
          filename="package://Poppy_Humanoid.SLDASM/meshes/l_thigh.STL" />
      </geometry>
    </collision>
  </link>
  <joint
    name="l_hip_y"
    type="continuous">
    <origin
      xyz="0 -0.0240000000000002 0"
      rpy="-0.0397561965411015 0 0" />
    <parent
      link="l_hip_motor" />
    <child
      link="l_thigh" />
    <axis
      xyz="1 0 0" />
  </joint>
  <link
    name="l_shin">
    <inertial>
      <origin
        xyz="0.00175439048415977 -0.13778648686367 0.0145076205633883"
        rpy="0 0 0" />
      <mass
        value="0.110773765518952" />
      <inertia
        ixx="0.000140366492930774"
        ixy="5.68753376501925E-06"
        ixz="2.69139467815362E-08"
        iyy="3.46855576078014E-05"
        iyz="5.17259162064107E-06"
        izz="0.000137816025744094" />
    </inertial>
    <visual>
      <origin
        xyz="0 0 0"
        rpy="0 0 0" />
      <geometry>
        <mesh
          filename="package://Poppy_Humanoid.SLDASM/meshes/l_shin.STL" />
      </geometry>
      <material
        name="">
        <color
          rgba="0.752941176470588 0.752941176470588 0.752941176470588 1" />
      </material>
    </visual>
    <collision>
      <origin
        xyz="0 0 0"
        rpy="0 0 0" />
      <geometry>
        <mesh
          filename="package://Poppy_Humanoid.SLDASM/meshes/l_shin.STL" />
      </geometry>
    </collision>
  </link>
  <joint
    name="l_knee_y"
    type="continuous">
    <origin
      xyz="0 -0.182 0"
      rpy="1.57079632679487 1.51589948598406 1.57079632679487" />
    <parent
      link="l_thigh" />
    <child
      link="l_shin" />
    <axis
      xyz="0 0 1" />
  </joint>
  <link
    name="l_foot">
    <inertial>
      <origin
        xyz="0.0158315064449795 -0.0257794291438067 0.0212221562447968"
        rpy="0 0 0" />
      <mass
        value="0.116031133606847" />
      <inertia
        ixx="5.27424778083277E-05"
        ixy="-2.39342047314727E-06"
        ixz="-5.77063021287203E-07"
        iyy="0.000104140022414631"
        iyz="8.54847327523374E-07"
        izz="5.69259581203808E-05" />
    </inertial>
    <visual>
      <origin
        xyz="0 0 0"
        rpy="0 0 0" />
      <geometry>
        <mesh
          filename="package://Poppy_Humanoid.SLDASM/meshes/l_foot.STL" />
      </geometry>
      <material
        name="">
        <color
          rgba="0.792156862745098 0.819607843137255 0.933333333333333 1" />
      </material>
    </visual>
    <collision>
      <origin
        xyz="0 0 0"
        rpy="0 0 0" />
      <geometry>
        <mesh
          filename="package://Poppy_Humanoid.SLDASM/meshes/l_foot.STL" />
      </geometry>
    </collision>
  </link>
  <joint
    name="l_ankle_y"
    type="continuous">
    <origin
      xyz="0 -0.18 0"
      rpy="-0.012865 -1.5708 -0.0022321" />
    <parent
      link="l_shin" />
    <child
      link="l_foot" />
    <axis
      xyz="0.99148 0.043977 0.12258" />
  </joint>
  <link
    name="abs_motors">
    <inertial>
      <origin
        xyz="-5.48350362776073E-05 0.0152825365080563 -0.0192562447248062"
        rpy="0 0 0" />
      <mass
        value="0.278825899491009" />
      <inertia
        ixx="9.61566837978232E-05"
        ixy="5.13836756258126E-07"
        ixz="2.75968910259614E-08"
        iyy="5.90114392897086E-05"
        iyz="-2.55122296538033E-06"
        izz="9.67806890552437E-05" />
    </inertial>
    <visual>
      <origin
        xyz="0 0 0"
        rpy="0 0 0" />
      <geometry>
        <mesh
          filename="package://Poppy_Humanoid.SLDASM/meshes/abs_motors.STL" />
      </geometry>
      <material
        name="">
        <color
          rgba="0.752941176470588 0.752941176470588 0.752941176470588 1" />
      </material>
    </visual>
    <collision>
      <origin
        xyz="0 0 0"
        rpy="0 0 0" />
      <geometry>
        <mesh
          filename="package://Poppy_Humanoid.SLDASM/meshes/abs_motors.STL" />
      </geometry>
    </collision>
  </link>
  <joint
    name="abs_y"
    type="continuous">
    <origin
      xyz="0 -0.017 0.061"
      rpy="1.51713961112434 0 0" />
    <parent
      link="pelvis" />
    <child
      link="abs_motors" />
    <axis
      xyz="-1 0 0" />
  </joint>
  <link
    name="abdomen">
    <inertial>
      <origin
        xyz="-0.000340210070582915 0.0455827262343428 -0.0207579934042731"
        rpy="0 0 0" />
      <mass
        value="0.037960508287074" />
      <inertia
        ixx="6.09517424586477E-05"
        ixy="-1.75287558565817E-09"
        ixz="-1.51493056100054E-08"
        iyy="6.12033215767998E-05"
        iyz="1.60999103001007E-06"
        izz="2.40268635968667E-05" />
    </inertial>
    <visual>
      <origin
        xyz="0 0 0"
        rpy="0 0 0" />
      <geometry>
        <mesh
          filename="package://Poppy_Humanoid.SLDASM/meshes/abdomen.STL" />
      </geometry>
      <material
        name="">
        <color
          rgba="1 1 1 1" />
      </material>
    </visual>
    <collision>
      <origin
        xyz="0 0 0"
        rpy="0 0 0" />
      <geometry>
        <mesh
          filename="package://Poppy_Humanoid.SLDASM/meshes/abdomen.STL" />
      </geometry>
    </collision>
  </link>
  <joint
    name="abs_x"
    type="continuous">
    <origin
      xyz="0 0 0"
      rpy="0 0 -0.00745867760389587" />
    <parent
      link="abs_motors" />
    <child
      link="abdomen" />
    <axis
      xyz="-0.000400012426098237 0.0536294809213152 -0.998560823768973" />
  </joint>
  <link
    name="spine">
    <inertial>
      <origin
        xyz="-0.000378587955310389 0.0293575549528429 -0.005777787461003"
        rpy="0 0 0" />
      <mass
        value="0.092944520006329" />
      <inertia
        ixx="3.19289822960603E-05"
        ixy="6.32169725720701E-08"
        ixz="2.07003346029649E-07"
        iyy="2.68379485071965E-05"
        iyz="-6.43003985666932E-07"
        izz="2.67601828490571E-05" />
    </inertial>
    <visual>
      <origin
        xyz="0 0 0"
        rpy="0 0 0" />
      <geometry>
        <mesh
          filename="package://Poppy_Humanoid.SLDASM/meshes/spine.STL" />
      </geometry>
      <material
        name="">
        <color
          rgba="0.752941176470588 0.752941176470588 0.752941176470588 1" />
      </material>
    </visual>
    <collision>
      <origin
        xyz="0 0 0"
        rpy="0 0 0" />
      <geometry>
        <mesh
          filename="package://Poppy_Humanoid.SLDASM/meshes/spine.STL" />
      </geometry>
    </collision>
  </link>
  <joint
    name="abs_z"
    type="continuous">
    <origin
      xyz="0 0.0515349232274412 0"
      rpy="0 0.038996312540617 0" />
    <parent
      link="abdomen" />
    <child
      link="spine" />
    <axis
      xyz="0.00953309201745728 -0.998533047993975 -0.053299833212197" />
  </joint>
  <link
    name="bust_motors">
    <inertial>
      <origin
        xyz="-0.000792823554767377 0.0115746562349981 -0.0096834988824604"
        rpy="0 0 0" />
      <mass
        value="0.15925970741798" />
      <inertia
        ixx="3.81956814308363E-05"
        ixy="4.64409719595272E-07"
        ixz="1.92509416416544E-08"
        iyy="2.56832611674282E-05"
        iyz="-1.06605701883586E-06"
        izz="3.84452606797824E-05" />
    </inertial>
    <visual>
      <origin
        xyz="0 0 0"
        rpy="0 0 0" />
      <geometry>
        <mesh
          filename="package://Poppy_Humanoid.SLDASM/meshes/bust_motors.STL" />
      </geometry>
      <material
        name="">
        <color
          rgba="0.752941176470588 0.752941176470588 0.752941176470588 1" />
      </material>
    </visual>
    <collision>
      <origin
        xyz="0 0 0"
        rpy="0 0 0" />
      <geometry>
        <mesh
          filename="package://Poppy_Humanoid.SLDASM/meshes/bust_motors.STL" />
      </geometry>
    </collision>
  </link>
  <joint
    name="bust_y"
    type="continuous">
    <origin
      xyz="0 0.0799525509774566 0.00280000000000001"
      rpy="0.0536951329733316 0 0" />
    <parent
      link="spine" />
    <child
      link="bust_motors" />
    <axis
      xyz="1 0 0" />
  </joint>
  <link
    name="chest">
    <inertial>
      <origin
        xyz="-0.00110378879046239 0.0520121492233439 0.000538805559547809"
        rpy="0 0 0" />
      <mass
        value="0.270930454261252" />
      <inertia
        ixx="0.000128525788578453"
        ixy="1.21027886957274E-07"
        ixz="-1.18656327168714E-06"
        iyy="0.000217984882639149"
        iyz="-2.81132312344967E-06"
        izz="0.000159915498863017" />
    </inertial>
    <visual>
      <origin
        xyz="0 0 0"
        rpy="0 0 0" />
      <geometry>
        <mesh
          filename="package://Poppy_Humanoid.SLDASM/meshes/chest.STL" />
      </geometry>
      <material
        name="">
        <color
          rgba="0.752941176470588 0.752941176470588 0.752941176470588 1" />
      </material>
    </visual>
    <collision>
      <origin
        xyz="0 0 0"
        rpy="0 0 0" />
      <geometry>
        <mesh
          filename="package://Poppy_Humanoid.SLDASM/meshes/chest.STL" />
      </geometry>
    </collision>
  </link>
  <joint
    name="bust_x"
    type="continuous">
    <origin
      xyz="0 0 0"
      rpy="0 0 0.00957078732054358" />
    <parent
      link="bust_motors" />
    <child
      link="chest" />
    <axis
      xyz="0 0 1" />
  </joint>
  <link
    name="neck">
    <inertial>
      <origin
        xyz="-0.000796426997055244 0.00855855330261018 0.0128349174679193"
        rpy="0 0 0" />
      <mass
        value="0.00592634977544095" />
      <inertia
        ixx="7.84935675033942E-07"
        ixy="5.98344889954351E-08"
        ixz="2.13209732420726E-07"
        iyy="2.41232945424174E-06"
        iyz="-2.09811733882228E-08"
        izz="2.62109471633833E-06" />
    </inertial>
    <visual>
      <origin
        xyz="0 0 0"
        rpy="0 0 0" />
      <geometry>
        <mesh
          filename="package://Poppy_Humanoid.SLDASM/meshes/neck.STL" />
      </geometry>
      <material
        name="">
        <color
          rgba="1 1 1 1" />
      </material>
    </visual>
    <collision>
      <origin
        xyz="0 0 0"
        rpy="0 0 0" />
      <geometry>
        <mesh
          filename="package://Poppy_Humanoid.SLDASM/meshes/neck.STL" />
      </geometry>
    </collision>
  </link>
  <joint
    name="head_z"
    type="continuous">
    <origin
      xyz="0 0.0839908898414324 0.00499999999999995"
      rpy="0 -0.150651615663017 0" />
    <parent
      link="chest" />
    <child
      link="neck" />
    <axis
      xyz="0 1 0" />
  </joint>
  <link
    name="head">
    <inertial>
      <origin
        xyz="-0.000840987900441241 0.0267555431647641 0.00820096196840817"
        rpy="0 0 0" />
      <mass
        value="0.163296019488925" />
      <inertia
        ixx="0.000176512902969783"
        ixy="-1.60798750039505E-06"
        ixz="1.58034182511937E-05"
        iyy="0.000221270073463045"
        iyz="1.56179942040681E-06"
        izz="0.000315860461068933" />
    </inertial>
    <visual>
      <origin
        xyz="0 0 0"
        rpy="0 0 0" />
      <geometry>
        <mesh
          filename="package://Poppy_Humanoid.SLDASM/meshes/head.STL" />
      </geometry>
      <material
        name="">
        <color
          rgba="0.752941176470588 0.752941176470588 0.752941176470588 1" />
      </material>
    </visual>
    <collision>
      <origin
        xyz="0 0 0"
        rpy="0 0 0" />
      <geometry>
        <mesh
          filename="package://Poppy_Humanoid.SLDASM/meshes/head.STL" />
      </geometry>
    </collision>
  </link>
  <joint
    name="head_y"
    type="continuous">
    <origin
      xyz="0 0.0200091101585678 0"
      rpy="-0.257122277257672 0 0" />
    <parent
      link="neck" />
    <child
      link="head" />
    <axis
      xyz="-0.993721899650089 -0.0284276983730277 0.108206525316315" />
  </joint>
  <link
    name="l_shoulder">
    <inertial>
      <origin
        xyz="0.00702535019049728 -0.00898079808037267 0.0116374577336697"
        rpy="0 0 0" />
      <mass
        value="0.00896396996812884" />
      <inertia
        ixx="3.6639768473731E-06"
        ixy="-2.76675835442336E-08"
        ixz="-2.58995803216685E-08"
        iyy="2.09966819936985E-06"
        iyz="-5.4411842319353E-08"
        izz="3.69080497614918E-06" />
    </inertial>
    <visual>
      <origin
        xyz="0 0 0"
        rpy="0 0 0" />
      <geometry>
        <mesh
          filename="package://Poppy_Humanoid.SLDASM/meshes/l_shoulder.STL" />
      </geometry>
      <material
        name="">
        <color
          rgba="1 1 1 1" />
      </material>
    </visual>
    <collision>
      <origin
        xyz="0 0 0"
        rpy="0 0 0" />
      <geometry>
        <mesh
          filename="package://Poppy_Humanoid.SLDASM/meshes/l_shoulder.STL" />
      </geometry>
    </collision>
  </link>
  <joint
    name="l_shoulder_y"
    type="continuous">
    <origin
      xyz="0.0785588930792943 0.0499999999999995 0.00399999999999989"
      rpy="0.0226593678827122 0 0" />
    <parent
      link="chest" />
    <child
      link="l_shoulder" />
    <axis
      xyz="-0.999257485297647 -0.00084937643055616 -0.0385195617355898" />
  </joint>
  <link
    name="l_shoulder_motor">
    <inertial>
      <origin
        xyz="-0.00851211778636021 -0.0112692693734319 0.0142589229036462"
        rpy="0 0 0" />
      <mass
        value="0.083878021282984" />
      <inertia
        ixx="1.87735368856798E-05"
        ixy="-2.92462053522239E-07"
        ixz="-1.05258034932422E-07"
        iyy="1.50674673926423E-05"
        iyz="2.48936438137363E-07"
        izz="2.18061923975924E-05" />
    </inertial>
    <visual>
      <origin
        xyz="0 0 0"
        rpy="0 0 0" />
      <geometry>
        <mesh
          filename="package://Poppy_Humanoid.SLDASM/meshes/l_shoulder_motor.STL" />
      </geometry>
      <material
        name="">
        <color
          rgba="0.752941176470588 0.752941176470588 0.752941176470588 1" />
      </material>
    </visual>
    <collision>
      <origin
        xyz="0 0 0"
        rpy="0 0 0" />
      <geometry>
        <mesh
          filename="package://Poppy_Humanoid.SLDASM/meshes/l_shoulder_motor.STL" />
      </geometry>
    </collision>
  </link>
  <joint
    name="l_shoulder_x"
    type="continuous">
    <origin
      xyz="0.0269411069207058 0 0"
      rpy="0 0 1.56874719947428" />
    <parent
      link="l_shoulder" />
    <child
      link="l_shoulder_motor" />
    <axis
      xyz="-0.999279815359569 -0.00435014137064167 -0.0376951838435841" />
  </joint>
  <link
    name="upper_arm">
    <inertial>
      <origin
        xyz="-0.0359808794476119 -0.0608597684603842 -0.0081369122117082"
        rpy="0 0 0" />
      <mass
        value="0.167374611533955" />
      <inertia
        ixx="5.92418965365081E-05"
        ixy="-4.33327962990833E-07"
        ixz="3.22101862820757E-07"
        iyy="3.95108036461607E-05"
        iyz="-3.91714342478269E-07"
        izz="5.30245695560206E-05" />
    </inertial>
    <visual>
      <origin
        xyz="0 0 0"
        rpy="0 0 0" />
      <geometry>
        <mesh
          filename="package://Poppy_Humanoid.SLDASM/meshes/upper_arm.STL" />
      </geometry>
      <material
        name="">
        <color
          rgba="0.752941176470588 0.752941176470588 0.752941176470588 1" />
      </material>
    </visual>
    <collision>
      <origin
        xyz="0 0 0"
        rpy="0 0 0" />
      <geometry>
        <mesh
          filename="package://Poppy_Humanoid.SLDASM/meshes/upper_arm.STL" />
      </geometry>
    </collision>
  </link>
  <joint
    name="l_arm_z"
    type="continuous">
    <origin
      xyz="0 -0.0374405904973501 -0.0185000000000006"
      rpy="3.14159265358979 1.5546131469944 3.14159265358979" />
    <parent
      link="l_shoulder_motor" />
    <child
      link="upper_arm" />
    <axis
      xyz="0 1 0" />
  </joint>
  <link
    name="l_forearm">
    <inertial>
      <origin
        xyz="-0.03490109083818 -0.10316750368298 -0.0356112408859482"
        rpy="0 0 0" />
      <mass
        value="0.0473266058471035" />
      <inertia
        ixx="6.01135934094006E-05"
        ixy="6.75112339123723E-07"
        ixz="7.2650269661061E-07"
        iyy="1.33719967902708E-05"
        iyz="-1.41583690626121E-06"
        izz="5.77919458835558E-05" />
    </inertial>
    <visual>
      <origin
        xyz="0 0 0"
        rpy="0 0 0" />
      <geometry>
        <mesh
          filename="package://Poppy_Humanoid.SLDASM/meshes/l_forearm.STL" />
      </geometry>
      <material
        name="">
        <color
          rgba="0.752941176470588 0.752941176470588 0.752941176470588 1" />
      </material>
    </visual>
    <collision>
      <origin
        xyz="0 0 0"
        rpy="0 0 0" />
      <geometry>
        <mesh
          filename="package://Poppy_Humanoid.SLDASM/meshes/l_forearm.STL" />
      </geometry>
    </collision>
  </link>
  <joint
    name="l_elbow_y"
    type="continuous">
    <origin
      xyz="0 -0.111559409502652 0.0100000000000002"
      rpy="-0.121325187109238 0 0" />
    <parent
      link="upper_arm" />
    <child
      link="l_forearm" />
    <axis
      xyz="1 0 0" />
  </joint>
  <link
    name="r_shoulder">
    <inertial>
      <origin
        xyz="-0.0101382507921527 -0.00470061306483078 -0.00924306258505636"
        rpy="0 0 0" />
      <mass
        value="0.008964773238563" />
      <inertia
        ixx="3.66019883902475E-06"
        ixy="-2.46129307149257E-08"
        ixz="3.38628736139256E-08"
        iyy="3.69136640360585E-06"
        iyz="8.98539946628872E-08"
        izz="2.10322950212028E-06" />
    </inertial>
    <visual>
      <origin
        xyz="0 0 0"
        rpy="0 0 0" />
      <geometry>
        <mesh
          filename="package://Poppy_Humanoid.SLDASM/meshes/r_shoulder.STL" />
      </geometry>
      <material
        name="">
        <color
          rgba="1 1 1 1" />
      </material>
    </visual>
    <collision>
      <origin
        xyz="0 0 0"
        rpy="0 0 0" />
      <geometry>
        <mesh
          filename="package://Poppy_Humanoid.SLDASM/meshes/r_shoulder.STL" />
      </geometry>
    </collision>
  </link>
  <joint
    name="r_shoulder_y"
    type="continuous">
    <origin
      xyz="-0.0785571680205247 0.0499999999999997 0.00399999999999994"
      rpy="-1.57193529946344 0 0" />
    <parent
      link="chest" />
    <child
      link="r_shoulder" />
    <axis
      xyz="-0.999257485297647 0.0385288661029548 6.74792047801718E-05" />
  </joint>
  <link
    name="r_shoulder_motor">
    <inertial>
      <origin
        xyz="0.00546768559321874 -0.0143696842116452 -0.00887127112376954"
        rpy="0 0 0" />
      <mass
        value="0.0838780210514258" />
      <inertia
        ixx="2.18084262695485E-05"
        ixy="-1.20411102146261E-08"
        ixz="-1.86015696082457E-07"
        iyy="1.50606332864897E-05"
        iyz="-3.02815062379624E-07"
        izz="1.877813691586E-05" />
    </inertial>
    <visual>
      <origin
        xyz="0 0 0"
        rpy="0 0 0" />
      <geometry>
        <mesh
          filename="package://Poppy_Humanoid.SLDASM/meshes/r_shoulder_motor.STL" />
      </geometry>
      <material
        name="">
        <color
          rgba="0.752941176470588 0.752941176470588 0.752941176470588 1" />
      </material>
    </visual>
    <collision>
      <origin
        xyz="0 0 0"
        rpy="0 0 0" />
      <geometry>
        <mesh
          filename="package://Poppy_Humanoid.SLDASM/meshes/r_shoulder_motor.STL" />
      </geometry>
    </collision>
  </link>
  <joint
    name="r_shoulder_x"
    type="continuous">
    <origin
      xyz="-0.0269428319794755 0 0"
      rpy="0 0 -1.59140124693212" />
    <parent
      link="r_shoulder" />
    <child
      link="r_shoulder_motor" />
    <axis
      xyz="-0.061498020607165 0.0010356297970523 -0.998106668113346" />
  </joint>
  <link
    name="r_upper_arm">
    <inertial>
      <origin
        xyz="0.00543135500640869 -0.0641812605481032 0.0100355714270552"
        rpy="0 0 0" />
      <mass
        value="0.167374646876886" />
      <inertia
        ixx="5.92486032857227E-05"
        ixy="-3.05908089383738E-07"
        ixz="-3.18668836757057E-07"
        iyy="3.95089228459743E-05"
        iyz="-4.26482067576107E-07"
        izz="5.30198572011604E-05" />
    </inertial>
    <visual>
      <origin
        xyz="0 0 0"
        rpy="0 0 0" />
      <geometry>
        <mesh
          filename="package://Poppy_Humanoid.SLDASM/meshes/r_upper_arm.STL" />
      </geometry>
      <material
        name="">
        <color
          rgba="0.752941176470588 0.752941176470588 0.752941176470588 1" />
      </material>
    </visual>
    <collision>
      <origin
        xyz="0 0 0"
        rpy="0 0 0" />
      <geometry>
        <mesh
          filename="package://Poppy_Humanoid.SLDASM/meshes/r_upper_arm.STL" />
      </geometry>
    </collision>
  </link>
  <joint
    name="r_arm_z"
    type="continuous">
    <origin
      xyz="0 -0.0372875842562274 -0.0184999999999999"
      rpy="0 -0.0424996253723622 0" />
    <parent
      link="r_shoulder_motor" />
    <child
      link="r_upper_arm" />
    <axis
      xyz="0 1 0" />
  </joint>
  <link
    name="r_forearm">
    <inertial>
      <origin
        xyz="-0.00212457048463193 -0.105078558548172 -0.0320072257870791"
        rpy="0 0 0" />
      <mass
        value="0.0473279796557709" />
      <inertia
        ixx="5.99919240372156E-05"
        ixy="-2.35624601458505E-06"
        ixz="-1.10035494185693E-06"
        iyy="1.46012934512543E-05"
        iyz="-7.05237910451498E-06"
        izz="5.6690553365564E-05" />
    </inertial>
    <visual>
      <origin
        xyz="0 0 0"
        rpy="0 0 0" />
      <geometry>
        <mesh
          filename="package://Poppy_Humanoid.SLDASM/meshes/r_forearm.STL" />
      </geometry>
      <material
        name="">
        <color
          rgba="0.752941176470588 0.752941176470588 0.752941176470588 1" />
      </material>
    </visual>
    <collision>
      <origin
        xyz="0 0 0"
        rpy="0 0 0" />
      <geometry>
        <mesh
          filename="package://Poppy_Humanoid.SLDASM/meshes/r_forearm.STL" />
      </geometry>
    </collision>
  </link>
  <joint
    name="r_elbow_y"
    type="continuous">
    <origin
      xyz="0 -0.11171 0.01"
      rpy="-0.23046 0 0" />
    <parent
      link="r_upper_arm" />
    <child
      link="r_forearm" />
    <axis
      xyz="1 0 0" />
  </joint>
</robot>